Workbook

Sheet Dashboard
A1: Healthcare Dashboard – AI Analysis
A5: Total Customers | C5: Total Healthcare Costs | E5: Avg Charge / Customer | G5: Avg BMI | I5: Avg Age | K5: % Smokers
A6: ='Summary & Pivots'!A5 -> 2335 | C6: ='Summary & Pivots'!E5 -> 31592359 | E6: ='Summary & Pivots'!G5 -> 13529.918 | G6: ='Summary & Pivots'!A8 -> 30.972649 | I6: ='Summary & Pivots'!E8 -> 0 | K6: ='Summary & Pivots'!G8 -> 0.20985011
G26: ACTION NEEDED (manual step, per assignment): 1. Click any cell in the "Healthcare" sheet → Insert → PivotTable → New Worksheet. 2. Build the pivot manually as instructed (Activity 1B/2), then Insert → Slicer → choose "Weight Status" and "Diabetes Status" → position slicers here. 3. Link each slicer to this dashboard's pivot charts via Report Connections (right-click slicer → Report Connections) so filters control every chart.

Sheet Customer Names
A1: Customer ID | B1: name | C1: Title | D1: First Name | E1: Last Name | F1: Name Remainder (helper)
A2: Id1 | B2: Hawks, Ms. Kelly | C2: =LEFT(F2,FIND(" ",F2&" ")-1) -> Ms. | D2: =TRIM(MID(F2,FIND(" ",F2&" ")+1,200)) -> Kelly | E2: =TRIM(LEFT(B2,FIND(",",B2)-1)) -> Hawks | F2: =TRIM(MID(B2,FIND(",",B2)+1,200)) -> Ms. Kelly
A3: Id2 | B3: Lehner, Mr. Matthew D | C3: =LEFT(F3,FIND(" ",F3&" ")-1) -> Mr. | D3: =TRIM(MID(F3,FIND(" ",F3&" ")+1,200)) -> Matthew D | E3: =TRIM(LEFT(B3,FIND(",",B3)-1)) -> Lehner | F3: =TRIM(MID(B3,FIND(",",B3)+1,200)) -> Mr. Matthew D
A4: Id3 | B4: Lu, Mr. Phil | C4: =LEFT(F4,FIND(" ",F4&" ")-1) -> Mr. | D4: =TRIM(MID(F4,FIND(" ",F4&" ")+1,200)) -> Phil | E4: =TRIM(LEFT(B4,FIND(",",B4)-1)) -> Lu | F4: =TRIM(MID(B4,FIND(",",B4)+1,200)) -> Mr. Phil
A5: Id4 | B5: Osborne, Ms. Kelsey | C5: =LEFT(F5,FIND(" ",F5&" ")-1) -> Ms. | D5: =TRIM(MID(F5,FIND(" ",F5&" ")+1,200)) -> Kelsey | E5: =TRIM(LEFT(B5,FIND(",",B5)-1)) -> Osborne | F5: =TRIM(MID(B5,FIND(",",B5)+1,200)) -> Ms. Kelsey
A6: Id5 | B6: Kadala, Ms. Kristyn | C6: =LEFT(F6,FIND(" ",F6&" ")-1) -> Ms. | D6: =TRIM(MID(F6,FIND(" ",F6&" ")+1,200)) -> Kristyn | E6: =TRIM(LEFT(B6,FIND(",",B6)-1)) -> Kadala | F6: =TRIM(MID(B6,FIND(",",B6)+1,200)) -> Ms. Kristyn
A7: Id6 | B7: Baker, Mr. Russell B. | C7: =LEFT(F7,FIND(" ",F7&" ")-1) -> Mr. | D7: =TRIM(MID(F7,FIND(" ",F7&" ")+1,200)) -> Russell B. | E7: =TRIM(LEFT(B7,FIND(",",B7)-1)) -> Baker | F7: =TRIM(MID(B7,FIND(",",B7)+1,200)) -> Mr. Russell B.
A8: Id7 | B8: Macpherson, Mr. Scott | C8: =LEFT(F8,FIND(" ",F8&" ")-1) -> Mr. | D8: =TRIM(MID(F8,FIND(" ",F8&" ")+1,200)) -> Scott | E8: =TRIM(LEFT(B8,FIND(",",B8)-1)) -> Macpherson | F8: =TRIM(MID(B8,FIND(",",B8)+1,200)) -> Mr. Scott
A9: Id8 | B9: Hallman, Mr. Stephen | C9: =LEFT(F9,FIND(" ",F9&" ")-1) -> Mr. | D9: =TRIM(MID(F9,FIND(" ",F9&" ")+1,200)) -> Stephen | E9: =TRIM(LEFT(B9,FIND(",",B9)-1)) -> Hallman | F9: =TRIM(MID(B9,FIND(",",B9)+1,200)) -> Mr. Stephen
A10: Id9 | B10: Moran, Mr. Patrick R. | C10: =LEFT(F10,FIND(" ",F10&" ")-1) -> Mr. | D10: =TRIM(MID(F10,FIND(" ",F10&" ")+1,200)) -> Patrick R. | E10: =TRIM(LEFT(B10,FIND(",",B10)-1)) -> Moran | F10: =TRIM(MID(B10,FIND(",",B10)+1,200)) -> Mr. Patrick R.
A11: Id10 | B11: Benner, Ms. Brooke N. | C11: =LEFT(F11,FIND(" ",F11&" ")-1) -> Ms. | D11: =TRIM(MID(F11,FIND(" ",F11&" ")+1,200)) -> Brooke N. | E11: =TRIM(LEFT(B11,FIND(",",B11)-1)) -> Benner | F11: =TRIM(MID(B11,FIND(",",B11)+1,200)) -> Ms. Brooke N.
A12: Id11 | B12: Fierro Vargas, Ms. Paola Andrea | C12: =LEFT(F12,FIND(" ",F12&" ")-1) -> Ms. | D12: =TRIM(MID(F12,FIND(" ",F12&" ")+1,200)) -> Paola Andrea | E12: =TRIM(LEFT(B12,FIND(",",B12)-1)) -> Fierro Vargas | F12: =TRIM(MID(B12,FIND(",",B12)+1,200)) -> Ms. Paola Andrea
A13: Id12 | B13: Franz, Mr. David | C13: =LEFT(F13,FIND(" ",F13&" ")-1) -> Mr. | D13: =TRIM(MID(F13,FIND(" ",F13&" ")+1,200)) -> David | E13: =TRIM(LEFT(B13,FIND(",",B13)-1)) -> Franz | F13: =TRIM(MID(B13,FIND(",",B13)+1,200)) -> Mr. David
... A2336: Id2335 | B2336: German, Mr. Aaron K | C2336: =LEFT(F2336,FIND(" ",F2336&" ")-1) -> Mr. | D2336: =TRIM(MID(F2336,FIND(" ",F2336&" ")+1,200)) -> Aaron K | E2336: =TRIM(LEFT(B2336,FIND(",",B2336)-1)) -> German | F2336: =TRIM(MID(B2336,FIND(",",B2336)+1,200)) -> Mr. Aaron K

Sheet Medical Examinations
A1: Customer ID | B1: BMI | C1: HBA1C | D1: Heart Issues | E1: Any Transplants | F1: Cancer history | G1: NumberOfMajorSurgeries | H1: smoker | I1: Heart Issues (Cleaned) | J1: Any Transplants (Cleaned) | K1: Smoker (Cleaned) | L1: NumberOfMajorSurgeries (Numeric) | M1: Weight Status | N1: Diabetes Status
A2: Id1 | B2: 47.41 | C2: 7.47 | D2: No | E2: No | F2: No | G2: No major surgery | H2: yes | I2: =PROPER(D2) -> No | J2: =PROPER(E2) -> No | K2: =IF(H2="?",$K$4,PROPER(H2)) -> Yes | L2: =IF(G2="No major surgery",0,G2) -> 0 | M2: =IF(B2<18.5,"Underweight",IF(B2<=24.9,"Normal Weight",IF(B2<=29.9,"Overweight","Obesity"))) -> Obesity | N2: =IF(C2<5.7,"Normal",IF(C2<=6.4,"Prediabetic","Diabetic")) -> Diabetic
A3: Id2 | B3: 30.36 | C3: 5.77 | D3: No | E3: No | F3: No | G3: No major surgery | H3: yes | I3: =PROPER(D3) -> No | J3: =PROPER(E3) -> No | K3: =IF(H3="?",$K$4,PROPER(H3)) -> Yes | L3: =IF(G3="No major surgery",0,G3) -> 0 | M3: =IF(B3<18.5,"Underweight",IF(B3<=24.9,"Normal Weight",IF(B3<=29.9,"Overweight","Obesity"))) -> Obesity | N3: =IF(C3<5.7,"Normal",IF(C3<=6.4,"Prediabetic","Diabetic")) -> Prediabetic
A4: Id3 | B4: 34.485 | C4: 11.87 | D4: yes | E4: No | F4: No | G4: 2 | H4: yes | I4: =PROPER(D4) -> Yes | J4: =PROPER(E4) -> No | K4: =IF(H4="?",$K$4,PROPER(H4)) -> Yes | L4: =IF(G4="No major surgery",0,G4) -> 2 | M4: =IF(B4<18.5,"Underweight",IF(B4<=24.9,"Normal Weight",IF(B4<=29.9,"Overweight","Obesity"))) -> Obesity | N4: =IF(C4<5.7,"Normal",IF(C4<=6.4,"Prediabetic","Diabetic")) -> Diabetic
A5: Id4 | B5: 38.095 | C5: 6.05 | D5: No | E5: No | F5: No | G5: No major surgery | H5: yes | I5: =PROPER(D5) -> No | J5: =PROPER(E5) -> No | K5: =IF(H5="?",$K$4,PROPER(H5)) -> Yes | L5: =IF(G5="No major surgery",0,G5) -> 0 | M5: =IF(B5<18.5,"Underweight",IF(B5<=24.9,"Normal Weight",IF(B5<=29.9,"Overweight","Obesity"))) -> Obesity | N5: =IF(C5<5.7,"Normal",IF(C5<=6.4,"Prediabetic","Diabetic")) -> Prediabetic
A6: Id5 | B6: 35.53 | C6: 5.45 | D6: No | E6: No | F6: No | G6: No major surgery | H6: yes | I6: =PROPER(D6) -> No | J6: =PROPER(E6) -> No | K6: =IF(H6="?",$K$4,PROPER(H6)) -> Yes | L6: =IF(G6="No major surgery",0,G6) -> 0 | M6: =IF(B6<18.5,"Underweight",IF(B6<=24.9,"Normal Weight",IF(B6<=29.9,"Overweight","Obesity"))) -> Obesity | N6: =IF(C6<5.7,"Normal",IF(C6<=6.4,"Prediabetic","Diabetic")) -> Normal
A7: Id6 | B7: 32.8 | C7: 6.59 | D7: No | E7: No | F7: No | G7: No major surgery | H7: yes | I7: =PROPER(D7) -> No | J7: =PROPER(E7) -> No | K7: =IF(H7="?",$K$4,PROPER(H7)) -> Yes | L7: =IF(G7="No major surgery",0,G7) -> 0 | M7: =IF(B7<18.5,"Underweight",IF(B7<=24.9,"Normal Weight",IF(B7<=29.9,"Overweight","Obesity"))) -> Obesity | N7: =IF(C7<5.7,"Normal",IF(C7<=6.4,"Prediabetic","Diabetic")) -> Diabetic
A8: Id7 | B8: 36.4 | C8: 6.07 | D8: No | E8: No | F8: No | G8: No major surgery | H8: yes | I8: =PROPER(D8) -> No | J8: =PROPER(E8) -> No | K8: =IF(H8="?",$K$4,PROPER(H8)) -> Yes | L8: =IF(G8="No major surgery",0,G8) -> 0 | M8: =IF(B8<18.5,"Underweight",IF(B8<=24.9,"Normal Weight",IF(B8<=29.9,"Overweight","Obesity"))) -> Obesity | N8: =IF(C8<5.7,"Normal",IF(C8<=6.4,"Prediabetic","Diabetic")) -> Prediabetic
A9: Id8 | B9: 36.96 | C9: 7.93 | D9: No | E9: No | F9: No | G9: 3 | H9: yes | I9: =PROPER(D9) -> No | J9: =PROPER(E9) -> No | K9: =IF(H9="?",$K$4,PROPER(H9)) -> Yes | L9: =IF(G9="No major surgery",0,G9) -> 3 | M9: =IF(B9<18.5,"Underweight",IF(B9<=24.9,"Normal Weight",IF(B9<=29.9,"Overweight","Obesity"))) -> Obesity | N9: =IF(C9<5.7,"Normal",IF(C9<=6.4,"Prediabetic","Diabetic")) -> Diabetic
A10: Id9 | B10: 41.14 | C10: 9.58 | D10: yes | E10: No | F10: Yes | G10: 1 | H10: yes | I10: =PROPER(D10) -> Yes | J10: =PROPER(E10) -> No | K10: =IF(H10="?",$K$4,PROPER(H10)) -> Yes | L10: =IF(G10="No major surgery",0,G10) -> 1 | M10: =IF(B10<18.5,"Underweight",IF(B10<=24.9,"Normal Weight",IF(B10<=29.9,"Overweight","Obesity"))) -> Obesity | N10: =IF(C10<5.7,"Normal",IF(C10<=6.4,"Prediabetic","Diabetic")) -> Diabetic
A11: Id10 | B11: 38.06 | C11: 10.79 | D11: No | E11: No | F11: No | G11: No major surgery | H11: yes | I11: =PROPER(D11) -> No | J11: =PROPER(E11) -> No | K11: =IF(H11="?",$K$4,PROPER(H11)) -> Yes | L11: =IF(G11="No major surgery",0,G11) -> 0 | M11: =IF(B11<18.5,"Underweight",IF(B11<=24.9,"Normal Weight",IF(B11<=29.9,"Overweight","Obesity"))) -> Obesity | N11: =IF(C11<5.7,"Normal",IF(C11<=6.4,"Prediabetic","Diabetic")) -> Diabetic
A12: Id11 | B12: 37.7 | C12: 5.96 | D12: yes | E12: No | F12: No | G12: 2 | H12: yes | I12: =PROPER(D12) -> Yes | J12: =PROPER(E12) -> No | K12: =IF(H12="?",$K$4,PROPER(H12)) -> Yes | L12: =IF(G12="No major surgery",0,G12) -> 2 | M12: =IF(B12<18.5,"Underweight",IF(B12<=24.9,"Normal Weight",IF(B12<=29.9,"Overweight","Obesity"))) -> Obesity | N12: =IF(C12<5.7,"Normal",IF(C12<=6.4,"Prediabetic","Diabetic")) -> Prediabetic
A13: Id12 | B13: 42.13 | C13: 11.9 | D13: No | E13: No | F13: No | G13: No major surgery | H13: yes | I13: =PROPER(D13) -> No | J13: =PROPER(E13) -> No | K13: =IF(H13="?",$K$4,PROPER(H13)) -> Yes | L13: =IF(G13="No major surgery",0,G13) -> 0 | M13: =IF(B13<18.5,"Underweight",IF(B13<=24.9,"Normal Weight",IF(B13<=29.9,"Overweight","Obesity"))) -> Obesity | N13: =IF(C13<5.7,"Normal",IF(C13<=6.4,"Prediabetic","Diabetic")) -> Diabetic
A14: Id13 | B14: 40.92 | C14: 8.41 | D14: No | E14: No | F14: No | G14: No major surgery | H14: yes | I14: =PROPER(D14) -> No | J14: =PROPER(E14) -> No | K14: =IF(H14="?",$K$4,PROPER(H14)) -> Yes | L14: =IF(G14="No major surgery",0,G14) -> 0 | M14: =IF(B14<18.5,"Underweight",IF(B14<=24.9,"Normal Weight",IF(B14<=29.9,"Overweight","Obesity"))) -> Obesity | N14: =IF(C14<5.7,"Normal",IF(C14<=6.4,"Prediabetic","Diabetic")) -> Diabetic
A15: Id14 | B15: 40.565 | C15: 7.02 | D15: No | E15: No | F15: No | G15: No major surgery | H15: yes | I15: =PROPER(D15) -> No | J15: =PROPER(E15) -> No | K15: =IF(H15="?",$K$4,PROPER(H15)) -> Yes | L15: =IF(G15="No major surgery",0,G15) -> 0 | M15: =IF(B15<18.5,"Underweight",IF(B15<=24.9,"Normal Weight",IF(B15<=29.9,"Overweight","Obesity"))) -> Obesity | N15: =IF(C15<5.7,"Normal",IF(C15<=6.4,"Prediabetic","Diabetic")) -> Diabetic
A16: Id15 | B16: 36.385 | C16: 7.59 | D16: yes | E16: No | F16: No | G16: 2 | H16: yes | I16: =PROPER(D16) -> Yes | J16: =PROPER(E16) -> No | K16: =IF(H16="?",$K$4,PROPER(H16)) -> Yes | L16: =IF(G16="No major surgery",0,G16) -> 2 | M16: =IF(B16<18.5,"Underweight",IF(B16<=24.9,"Normal Weight",IF(B16<=29.9,"Overweight","Obesity"))) -> Obesity | N16: =IF(C16<5.7,"Normal",IF(C16<=6.4,"Prediabetic","Diabetic")) -> Diabetic
A17: Id16 | B17: 39.9 | C17: 11.32 | D17: No | E17: No | F17: No | G17: No major surgery | H17: yes | I17: =PROPER(D17) -> No | J17: =PROPER(E17) -> No | K17: =IF(H17="?",$K$4,PROPER(H17)) -> Yes | L17: =IF(G17="No major surgery",0,G17) -> 0 | M17: =IF(B17<18.5,"Underweight",IF(B17<=24.9,"Normal Weight",IF(B17<=29.9,"Overweight","Obesity"))) -> Obesity | N17: =IF(C17<5.7,"Normal",IF(C17<=6.4,"Prediabetic","Diabetic")) -> Diabetic
A18: Id17 | B18: 33.8 | C18: 7.67 | D18: No | E18: No | F18: No | G18: 3 | H18: yes | I18: =PROPER(D18) -> No | J18: =PROPER(E18) -> No | K18: =IF(H18="?",$K$4,PROPER(H18)) -> Yes | L18: =IF(G18="No major surgery",0,G18) -> 3 | M18: =IF(B18<18.5,"Underweight",IF(B18<=24.9,"Normal Weight",IF(B18<=29.9,"Overweight","Obesity"))) -> Obesity | N18: =IF(C18<5.7,"Normal",IF(C18<=6.4,"Prediabetic","Diabetic")) -> Diabetic
A19: Id18 | B19: 36.765 | C19: 7.29 | D19: yes | E19: No | F19: Yes | G19: 1 | H19: yes | I19: =PROPER(D19) -> Yes | J19: =PROPER(E19) -> No | K19: =IF(H19="?",$K$4,PROPER(H19)) -> Yes | L19: =IF(G19="No major surgery",0,G19) -> 1 | M19: =IF(B19<18.5,"Underweight",IF(B19<=24.9,"Normal Weight",IF(B19<=29.9,"Overweight","Obesity"))) -> Obesity | N19: =IF(C19<5.7,"Normal",IF(C19<=6.4,"Prediabetic","Diabetic")) -> Diabetic
A20: Id19 | B20: 36.955 | C20: 4.72 | D20: yes | E20: No | F20: No | G20: 1 | H20: yes | I20: =PROPER(D20) -> Yes | J20: =PROPER(E20) -> No | K20: =IF(H20="?",$K$4,PROPER(H20)) -> Yes | L20: =IF(G20="No major surgery",0,G20) -> 1 | M20: =IF(B20<18.5,"Underweight",IF(B20<=24.9,"Normal Weight",IF(B20<=29.9,"Overweight","Obesity"))) -> Obesity | N20: =IF(C20<5.7,"Normal",IF(C20<=6.4,"Prediabetic","Diabetic")) -> Normal
A21: Id20 | B21: 42.9 | C21: 11.41 | D21: No | E21: No | F21: No | G21: No major surgery | H21: yes | I21: =PROPER(D21) -> No | J21: =PROPER(E21) -> No | K21: =IF(H21="?",$K$4,PROPER(H21)) -> Yes | L21: =IF(G21="No major surgery",0,G21) -> 0 | M21: =IF(B21<18.5,"Underweight",IF(B21<=24.9,"Normal Weight",IF(B21<=29.9,"Overweight","Obesity"))) -> Obesity | N21: =IF(C21<5.7,"Normal",IF(C21<=6.4,"Prediabetic","Diabetic")) -> Diabetic
A22: Id21 | B22: 36.3 | C22: 11.5 | D22: yes | E22: No | F22: No | G22: 2 | H22: yes | I22: =PROPER(D22) -> Yes | J22: =PROPER(E22) -> No | K22: =IF(H22="?",$K$4,PROPER(H22)) -> Yes | L22: =IF(G22="No major surgery",0,G22) -> 2 | M22: =IF(B22<18.5,"Underweight",IF(B22<=24.9,"Normal Weight",IF(B22<=29.9,"Overweight","Obesity"))) -> Obesity | N22: =IF(C22<5.7,"Normal",IF(C22<=6.4,"Prediabetic","Diabetic")) -> Diabetic
A23: Id22 | B23: 32.2 | C23: 6.22 | D23: yes | E23: No | F23: No | G23: 2 | H23: yes | I23: =PROPER(D23) -> Yes | J23: =PROPER(E23) -> No | K23: =IF(H23="?",$K$4,PROPER(H23)) -> Yes | L23: =IF(G23="No major surgery",0,G23) -> 2 | M23: =IF(B23<18.5,"Underweight",IF(B23<=24.9,"Normal Weight",IF(B23<=29.9,"Overweight","Obesity"))) -> Obesity | N23: =IF(C23<5.7,"Normal",IF(C23<=6.4,"Prediabetic","Diabetic")) -> Prediabetic
A24: Id23 | B24: 31.3 | C24: 11.38 | D24: No | E24: No | F24: No | G24: 3 | H24: yes | I24: =PROPER(D24) -> No | J24: =PROPER(E24) -> No | K24: =IF(H24="?",$K$4,PROPER(H24)) -> Yes | L24: =IF(G24="No major surgery",0,G24) -> 3 | M24: =IF(B24<18.5,"Underweight",IF(B24<=24.9,"Normal Weight",IF(B24<=29.9,"Overweight","Obesity"))) -> Obesity | N24: =IF(C24<5.7,"Normal",IF(C24<=6.4,"Prediabetic","Diabetic")) -> Diabetic
A25: Id24 | B25: 41.8 | C25: 7.89 | D25: yes | E25: No | F25: No | G25: 2 | H25: yes | I25: =PROPER(D25) -> Yes | J25: =PROPER(E25) -> No | K25: =IF(H25="?",$K$4,PROPER(H25)) -> Yes | L25: =IF(G25="No major surgery",0,G25) -> 2 | M25: =IF(B25<18.5,"Underweight",IF(B25<=24.9,"Normal Weight",IF(B25<=29.9,"Overweight","Obesity"))) -> Obesity | N25: =IF(C25<5.7,"Normal",IF(C25<=6.4,"Prediabetic","Diabetic")) -> Diabetic
A26: Id25 | B26: 35.09 | C26: 4.38 | D26: yes | E26: No | F26: No | G26: 2 | H26: yes | I26: =PROPER(D26) -> Yes | J26: =PROPER(E26) -> No | K26: =IF(H26="?",$K$4,PROPER(H26)) -> Yes | L26: =IF(G26="No major surgery",0,G26) -> 2 | M26: =IF(B26<18.5,"Underweight",IF(B26<=24.9,"Normal Weight",IF(B26<=29.9,"Overweight","Obesity"))) -> Obesity | N26: =IF(C26<5.7,"Normal",IF(C26<=6.4,"Prediabetic","Diabetic")) -> Normal
A27: Id26 | B27: 33.88 | C27: 7.01 | D27: No | E27: No | F27: No | G27: 3 | H27: yes | I27: =PROPER(D27) -> No | J27: =PROPER(E27) -> No | K27: =IF(H27="?",$K$4,PROPER(H27)) -> Yes | L27: =IF(G27="No major surgery",0,G27) -> 3 | M27: =IF(B27<18.5,"Underweight",IF(B27<=24.9,"Normal Weight",IF(B27<=29.9,"Overweight","Obesity"))) -> Obesity | N27: =IF(C27<5.7,"Normal",IF(C27<=6.4,"Prediabetic","Diabetic")) -> Diabetic
A28: Id27 | B28: 30.875 | C28: 11.88 | D28: No | E28: No | F28: No | G28: No major surgery | H28: yes | I28: =PROPER(D28) -> No | J28: =PROPER(E28) -> No | K28: =IF(H28="?",$K$4,PROPER(H28)) -> Yes | L28: =IF(G28="No major surgery",0,G28) -> 0 | M28: =IF(B28<18.5,"Underweight",IF(B28<=24.9,"Normal Weight",IF(B28<=29.9,"Overweight","Obesity"))) -> Obesity | N28: =IF(C28<5.7,"Normal",IF(C28<=6.4,"Prediabetic","Diabetic")) -> Diabetic
A29: Id28 | B29: 36.86 | C29: 5.19 | D29: yes | E29: No | F29: Yes | G29: 1 | H29: yes | I29: =PROPER(D29) -> Yes | J29: =PROPER(E29) -> No | K29: =IF(H29="?",$K$4,PROPER(H29)) -> Yes | L29: =IF(G29="No major surgery",0,G29) -> 1 | M29: =IF(B29<18.5,"Underweight",IF(B29<=24.9,"Normal Weight",IF(B29<=29.9,"Overweight","Obesity"))) -> Obesity | N29: =IF(C29<5.7,"Normal",IF(C29<=6.4,"Prediabetic","Diabetic")) -> Normal
A30: Id29 | B30: 35.86 | C30: 6.74 | D30: yes | E30: No | F30: No | G30: 2 | H30: yes | I30: =PROPER(D30) -> Yes | J30: =PROPER(E30) -> No | K30: =IF(H30="?",$K$4,PROPER(H30)) -> Yes | L30: =IF(G30="No major surgery",0,G30) -> 2 | M30: =IF(B30<18.5,"Underweight",IF(B30<=24.9,"Normal Weight",IF(B30<=29.9,"Overweight","Obesity"))) -> Obesity | N30: =IF(C30<5.7,"Normal",IF(C30<=6.4,"Prediabetic","Diabetic")) -> Diabetic
A31: Id30 | B31: 37.05 | C31: 8.44 | D31: No | E31: No | F31: No | G31: No major surgery | H31: yes | I31: =PROPER(D31) -> No | J31: =PROPER(E31) -> No | K31: =IF(H31="?",$K$4,PROPER(H31)) -> Yes | L31: =IF(G31="No major surgery",0,G31) -> 0 | M31: =IF(B31<18.5,"Underweight",IF(B31<=24.9,"Normal Weight",IF(B31<=29.9,"Overweight","Obesity"))) -> Obesity | N31: =IF(C31<5.7,"Normal",IF(C31<=6.4,"Prediabetic","Diabetic")) -> Diabetic
A32: Id31 | B32: 43.89 | C32: 8.71 | D32: No | E32: No | F32: No | G32: No major surgery | H32: yes | I32: =PROPER(D32) -> No | J32: =PROPER(E32) -> No | K32: =IF(H32="?",$K$4,PROPER(H32)) -> Yes | L32: =IF(G32="No major surgery",0,G32) -> 0 | M32: =IF(B32<18.5,"Underweight",IF(B32<=24.9,"Normal Weight",IF(B32<=29.9,"Overweight","Obesity"))) -> Obesity | N32: =IF(C32<5.7,"Normal",IF(C32<=6.4,"Prediabetic","Diabetic")) -> Diabetic
A33: Id32 | B33: 42.35 | C33: 5.08 | D33: yes | E33: No | F33: No | G33: No major surgery | H33: yes | I33: =PROPER(D33) -> Yes | J33: =PROPER(E33) -> No | K33: =IF(H33="?",$K$4,PROPER(H33)) -> Yes | L33: =IF(G33="No major surgery",0,G33) -> 0 | M33: =IF(B33<18.5,"Underweight",IF(B33<=24.9,"Normal Weight",IF(B33<=29.9,"Overweight","Obesity"))) -> Obesity | N33: =IF(C33<5.7,"Normal",IF(C33<=6.4,"Prediabetic","Diabetic")) -> Normal
A34: Id33 | B34: 31.35 | C34: 6.86 | D34: No | E34: No | F34: No | G34: No major surgery | H34: yes | I34: =PROPER(D34) -> No | J34: =PROPER(E34) -> No | K34: =IF(H34="?",$K$4,PROPER(H34)) -> Yes | L34: =IF(G34="No major surgery",0,G34) -> 0 | M34: =IF(B34<18.5,"Underweight",IF(B34<=24.9,"Normal Weight",IF(B34<=29.9,"Overweight","Obesity"))) -> Obesity | N34: =IF(C34<5.7,"Normal",IF(C34<=6.4,"Prediabetic","Diabetic")) -> Diabetic
A35: Id34 | B35: 47.6 | C35: 5.95 | D35: yes | E35: No | F35: No | G35: No major surgery | H35: yes | I35: =PROPER(D35) -> Yes | J35: =PROPER(E35) -> No | K35: =IF(H35="?",$K$4,PROPER(H35)) -> Yes | L35: =IF(G35="No major surgery",0,G35) -> 0 | M35: =IF(B35<18.5,"Underweight",IF(B35<=24.9,"Normal Weight",IF(B35<=29.9,"Overweight","Obesity"))) -> Obesity | N35: =IF(C35<5.7,"Normal",IF(C35<=6.4,"Prediabetic","Diabetic")) -> Prediabetic
A36: Id35 | B36: 46.2 | C36: 6.09 | D36: No | E36: No | F36: Yes | G36: 1 | H36: yes | I36: =PROPER(D36) -> No | J36: =PROPER(E36) -> No | K36: =IF(H36="?",$K$4,PROPER(H36)) -> Yes | L36: =IF(G36="No major surgery",0,G36) -> 1 | M36: =IF(B36<18.5,"Underweight",IF(B36<=24.9,"Normal Weight",IF(B36<=29.9,"Overweight","Obesity"))) -> Obesity | N36: =IF(C36<5.7,"Normal",IF(C36<=6.4,"Prediabetic","Diabetic")) -> Prediabetic
A37: Id36 | B37: 32.015 | C37: 11.75 | D37: No | E37: No | F37: No | G37: No major surgery | H37: yes | I37: =PROPER(D37) -> No | J37: =PROPER(E37) -> No | K37: =IF(H37="?",$K$4,PROPER(H37)) -> Yes | L37: =IF(G37="No major surgery",0,G37) -> 0 | M37: =IF(B37<18.5,"Underweight",IF(B37<=24.9,"Normal Weight",IF(B37<=29.9,"Overweight","Obesity"))) -> Obesity | N37: =IF(C37<5.7,"Normal",IF(C37<=6.4,"Prediabetic","Diabetic")) -> Diabetic
A38: Id37 | B38: 40.565 | C38: 7.37 | D38: No | E38: No | F38: No | G38: No major surgery | H38: yes | I38: =PROPER(D38) -> No | J38: =PROPER(E38) -> No | K38: =IF(H38="?",$K$4,PROPER(H38)) -> Yes | L38: =IF(G38="No major surgery",0,G38) -> 0 | M38: =IF(B38<18.5,"Underweight",IF(B38<=24.9,"Normal Weight",IF(B38<=29.9,"Overweight","Obesity"))) -> Obesity | N38: =IF(C38<5.7,"Normal",IF(C38<=6.4,"Prediabetic","Diabetic")) -> Diabetic
A39: Id38 | B39: 32.45 | C39: 11.91 | D39: No | E39: No | F39: No | G39: No major surgery | H39: yes | I39: =PROPER(D39) -> No | J39: =PROPER(E39) -> No | K39: =IF(H39="?",$K$4,PROPER(H39)) -> Yes | L39: =IF(G39="No major surgery",0,G39) -> 0 | M39: =IF(B39<18.5,"Underweight",IF(B39<=24.9,"Normal Weight",IF(B39<=29.9,"Overweight","Obesity"))) -> Obesity | N39: =IF(C39<5.7,"Normal",IF(C39<=6.4,"Prediabetic","Diabetic")) -> Diabetic
A40: Id39 | B40: 34.96 | C40: 6.52 | D40: No | E40: No | F40: No | G40: No major surgery | H40: yes | I40: =PROPER(D40) -> No | J40: =PROPER(E40) -> No | K40: =IF(H40="?",$K$4,PROPER(H40)) -> Yes | L40: =IF(G40="No major surgery",0,G40) -> 0 | M40: =IF(B40<18.5,"Underweight",IF(B40<=24.9,"Normal Weight",IF(B40<=29.9,"Overweight","Obesity"))) -> Obesity | N40: =IF(C40<5.7,"Normal",IF(C40<=6.4,"Prediabetic","Diabetic")) -> Diabetic
...

Sheet Hospitalisation Details
A1: Customer ID | B1: year | C1: month | D1: date | E1: children | F1: charges | G1: Hospital tier | H1: City tier | I1: State ID | J1: Hospital Tier Mode Calc | K1: Column2 | L1: City Tier Mode Calc | M1: Column4 | N1: Year (Cleaned) | O1: Month (Cleaned) | P1: Hospital Tier (Cleaned) | Q1: City Tier (Cleaned) | R1: State ID (Cleaned) | S1: Date of Birth | T1: Age
A2: Id2335 | B2: 1992 | C2: Jul | D2: 9 | E2: 0 | F2: 563.84 | G2: tier - 2 | H2: tier - 3 | I2: R1013 | J2: tier - 1 | K2: =COUNTIF($G$2:$G$2344,J2) -> 309 | L2: tier - 1 | M2: =COUNTIF($H$2:$H$2344,L2) -> 734 | N2: =IF(B2="?",ROUND(AVERAGE($B$2:$B$2344),0),B2) -> 1992 | O2: =IF(C2="?","Sep",C2) -> Jul | P2: =IF(G2="?",$K$5,G2) -> tier - 2 | Q2: =IF(H2="?",$M$5,H2) -> tier - 3 | R2: =IF(I2="?","Unknown",I2) -> R1013 | S2: =IFERROR(DATE(N2,MONTH(DATEVALUE(O2&"-1")),D2),"") -> 33794 | T2: =IFERROR(DATEDIF(S2,DATE(2023,6,8),"y"),"") -> 30
A3: Id2334 | B3: 1992 | C3: Nov | D3: 30 | E3: 0 | F3: 570.62 | G3: tier - 2 | H3: tier - 1 | I3: R1013 | J3: tier - 2 | K3: =COUNTIF($G$2:$G$2344,J3) -> 1339 | L3: tier - 2 | M3: =COUNTIF($H$2:$H$2344,L3) -> 812 | N3: =IF(B3="?",ROUND(AVERAGE($B$2:$B$2344),0),B3) -> 1992 | O3: =IF(C3="?","Sep",C3) -> Nov | P3: =IF(G3="?",$K$5,G3) -> tier - 2 | Q3: =IF(H3="?",$M$5,H3) -> tier - 1 | R3: =IF(I3="?","Unknown",I3) -> R1013 | S3: =IFERROR(DATE(N3,MONTH(DATEVALUE(O3&"-1")),D3),"") -> 33938 | T3: =IFERROR(DATEDIF(S3,DATE(2023,6,8),"y"),"") -> 30
A4: Id2333 | B4: 1993 | C4: Jun | D4: 30 | E4: 0 | F4: 600 | G4: tier - 2 | H4: tier - 1 | I4: R1013 | J4: tier - 3 | K4: =COUNTIF($G$2:$G$2344,J4) -> 694 | L4: tier - 3 | M4: =COUNTIF($H$2:$H$2344,L4) -> 796 | N4: =IF(B4="?",ROUND(AVERAGE($B$2:$B$2344),0),B4) -> 1993 | O4: =IF(C4="?","Sep",C4) -> Jun | P4: =IF(G4="?",$K$5,G4) -> tier - 2 | Q4: =IF(H4="?",$M$5,H4) -> tier - 1 | R4: =IF(I4="?","Unknown",I4) -> R1013 | S4: =IFERROR(DATE(N4,MONTH(DATEVALUE(O4&"-1")),D4),"") -> 34150 | T4: =IFERROR(DATEDIF(S4,DATE(2023,6,8),"y"),"") -> 29
A5: Id2332 | B5: 1992 | C5: Sep | D5: 13 | E5: 0 | F5: 604.54 | G5: tier - 3 | H5: tier - 3 | I5: R1013 | J5: Mode: | K5: =INDEX(J2:J4,MATCH(MAX(K2:K4),K2:K4,0)) -> tier - 2 | L5: Mode: | M5: =INDEX(L2:L4,MATCH(MAX(M2:M4),M2:M4,0)) -> tier - 2 | N5: =IF(B5="?",ROUND(AVERAGE($B$2:$B$2344),0),B5) -> 1992 | O5: =IF(C5="?","Sep",C5) -> Sep | P5: =IF(G5="?",$K$5,G5) -> tier - 3 | Q5: =IF(H5="?",$M$5,H5) -> tier - 3 | R5: =IF(I5="?","Unknown",I5) -> R1013 | S5: =IFERROR(DATE(N5,MONTH(DATEVALUE(O5&"-1")),D5),"") -> 33860 | T5: =IFERROR(DATEDIF(S5,DATE(2023,6,8),"y"),"") -> 30
A6: Id2331 | B6: 1998 | C6: Jul | D6: 27 | E6: 0 | F6: 637.26 | G6: tier - 3 | H6: tier - 3 | I6: R1013 | N6: =IF(B6="?",ROUND(AVERAGE($B$2:$B$2344),0),B6) -> 1998 | O6: =IF(C6="?","Sep",C6) -> Jul | P6: =IF(G6="?",$K$5,G6) -> tier - 3 | Q6: =IF(H6="?",$M$5,H6) -> tier - 3 | R6: =IF(I6="?","Unknown",I6) -> R1013 | S6: =IFERROR(DATE(N6,MONTH(DATEVALUE(O6&"-1")),D6),"") -> 36003 | T6: =IFERROR(DATEDIF(S6,DATE(2023,6,8),"y"),"") -> 24
A7: Id2330 | B7: 2001 | C7: Nov | D7: 20 | E7: 0 | F7: 646.14 | G7: tier - 3 | H7: tier - 3 | I7: R1012 | N7: =IF(B7="?",ROUND(AVERAGE($B$2:$B$2344),0),B7) -> 2001 | O7: =IF(C7="?","Sep",C7) -> Nov | P7: =IF(G7="?",$K$5,G7) -> tier - 3 | Q7: =IF(H7="?",$M$5,H7) -> tier - 3 | R7: =IF(I7="?","Unknown",I7) -> R1012 | S7: =IFERROR(DATE(N7,MONTH(DATEVALUE(O7&"-1")),D7),"") -> 37215 | T7: =IFERROR(DATEDIF(S7,DATE(2023,6,8),"y"),"") -> 21
A8: Id2329 | B8: 1993 | C8: Jun | D8: 1 | E8: 0 | F8: 650 | G8: tier - 3 | H8: tier - 3 | I8: R1013 | N8: =IF(B8="?",ROUND(AVERAGE($B$2:$B$2344),0),B8) -> 1993 | O8: =IF(C8="?","Sep",C8) -> Jun | P8: =IF(G8="?",$K$5,G8) -> tier - 3 | Q8: =IF(H8="?",$M$5,H8) -> tier - 3 | R8: =IF(I8="?","Unknown",I8) -> R1013 | S8: =IFERROR(DATE(N8,MONTH(DATEVALUE(O8&"-1")),D8),"") -> 34121 | T8: =IFERROR(DATEDIF(S8,DATE(2023,6,8),"y"),"") -> 30
A9: Id2328 | B9: 1995 | C9: Jul | D9: 4 | E9: 0 | F9: 650 | G9: tier - 3 | H9: tier - 3 | I9: R1013 | N9: =IF(B9="?",ROUND(AVERAGE($B$2:$B$2344),0),B9) -> 1995 | O9: =IF(C9="?","Sep",C9) -> Jul | P9: =IF(G9="?",$K$5,G9) -> tier - 3 | Q9: =IF(H9="?",$M$5,H9) -> tier - 3 | R9: =IF(I9="?","Unknown",I9) -> R1013 | S9: =IFERROR(DATE(N9,MONTH(DATEVALUE(O9&"-1")),D9),"") -> 34884 | T9: =IFERROR(DATEDIF(S9,DATE(2023,6,8),"y"),"") -> 27
A10: Id2327 | B10: 2002 | C10: Nov | D10: 29 | E10: 0 | F10: 668 | G10: tier - 3 | H10: tier - 2 | I10: R1012 | N10: =IF(B10="?",ROUND(AVERAGE($B$2:$B$2344),0),B10) -> 2002 | O10: =IF(C10="?","Sep",C10) -> Nov | P10: =IF(G10="?",$K$5,G10) -> tier - 3 | Q10: =IF(H10="?",$M$5,H10) -> tier - 2 | R10: =IF(I10="?","Unknown",I10) -> R1012 | S10: =IFERROR(DATE(N10,MONTH(DATEVALUE(O10&"-1")),D10),"") -> 37589 | T10: =IFERROR(DATEDIF(S10,DATE(2023,6,8),"y"),"") -> 20
A11: Id2326 | B11: 1997 | C11: Nov | D11: 9 | E11: 0 | F11: 670 | G11: tier - 3 | H11: tier - 3 | I11: R1013 | N11: =IF(B11="?",ROUND(AVERAGE($B$2:$B$2344),0),B11) -> 1997 | O11: =IF(C11="?","Sep",C11) -> Nov | P11: =IF(G11="?",$K$5,G11) -> tier - 3 | Q11: =IF(H11="?",$M$5,H11) -> tier - 3 | R11: =IF(I11="?","Unknown",I11) -> R1013 | S11: =IFERROR(DATE(N11,MONTH(DATEVALUE(O11&"-1")),D11),"") -> 35743 | T11: =IFERROR(DATEDIF(S11,DATE(2023,6,8),"y"),"") -> 25
A12: Id2325 | B12: 2001 | C12: Sep | D12: 12 | E12: 0 | F12: 687.54 | G12: tier - 3 | H12: tier - 2 | I12: R1013 | N12: =IF(B12="?",ROUND(AVERAGE($B$2:$B$2344),0),B12) -> 2001 | O12: =IF(C12="?","Sep",C12) -> Sep | P12: =IF(G12="?",$K$5,G12) -> tier - 3 | Q12: =IF(H12="?",$M$5,H12) -> tier - 2 | R12: =IF(I12="?","Unknown",I12) -> R1013 | S12: =IFERROR(DATE(N12,MONTH(DATEVALUE(O12&"-1")),D12),"") -> 37146 | T12: =IFERROR(DATEDIF(S12,DATE(2023,6,8),"y"),"") -> 21
A13: Id2324 | B13: 1999 | C13: Dec | D13: 26 | E13: 0 | F13: 700 | G13: ? | H13: tier - 3 | I13: R1013 | N13: =IF(B13="?",ROUND(AVERAGE($B$2:$B$2344),0),B13) -> 1999 | O13: =IF(C13="?","Sep",C13) -> Dec | P13: =IF(G13="?",$K$5,G13) -> tier - 2 | Q13: =IF(H13="?",$M$5,H13) -> tier - 3 | R13: =IF(I13="?","Unknown",I13) -> R1013 | S13: =IFERROR(DATE(N13,MONTH(DATEVALUE(O13&"-1")),D13),"") -> 36520 | T13: =IFERROR(DATEDIF(S13,DATE(2023,6,8),"y"),"") -> 23
A14: Id2323 | B14: 1999 | C14: Dec | D14: 14 | E14: 0 | F14: 722.99 | G14: tier - 3 | H14: tier - 1 | I14: R1013 | N14: =IF(B14="?",ROUND(AVERAGE($B$2:$B$2344),0),B14) -> 1999 | O14: =IF(C14="?","Sep",C14) -> Dec | P14: =IF(G14="?",$K$5,G14) -> tier - 3 | Q14: =IF(H14="?",$M$5,H14) -> tier - 1 | R14: =IF(I14="?","Unknown",I14) -> R1013 | S14: =IFERROR(DATE(N14,MONTH(DATEVALUE(O14&"-1")),D14),"") -> 36508 | T14: =IFERROR(DATEDIF(S14,DATE(2023,6,8),"y"),"") -> 23
A15: Id2322 | B15: 2002 | C15: ? | D15: 19 | E15: 0 | F15: 750 | G15: tier - 3 | H15: tier - 1 | I15: R1012 | N15: =IF(B15="?",ROUND(AVERAGE($B$2:$B$2344),0),B15) -> 2002 | O15: =IF(C15="?","Sep",C15) -> Sep | P15: =IF(G15="?",$K$5,G15) -> tier - 3 | Q15: =IF(H15="?",$M$5,H15) -> tier - 1 | R15: =IF(I15="?","Unknown",I15) -> R1012 | S15: =IFERROR(DATE(N15,MONTH(DATEVALUE(O15&"-1")),D15),"") -> 37518 | T15: =IFERROR(DATEDIF(S15,DATE(2023,6,8),"y"),"") -> 20
A16: Id2321 | B16: 1993 | C16: Aug | D16: 9 | E16: 0 | F16: 760 | G16: tier - 3 | H16: tier - 1 | I16: R1013 | N16: =IF(B16="?",ROUND(AVERAGE($B$2:$B$2344),0),B16) -> 1993 | O16: =IF(C16="?","Sep",C16) -> Aug | P16: =IF(G16="?",$K$5,G16) -> tier - 3 | Q16: =IF(H16="?",$M$5,H16) -> tier - 1 | R16: =IF(I16="?","Unknown",I16) -> R1013 | S16: =IFERROR(DATE(N16,MONTH(DATEVALUE(O16&"-1")),D16),"") -> 34190 | T16: =IFERROR(DATEDIF(S16,DATE(2023,6,8),"y"),"") -> 29
A17: Id2320 | B17: 1996 | C17: Oct | D17: 22 | E17: 0 | F17: 760 | G17: tier - 3 | H17: tier - 3 | I17: R1013 | N17: =IF(B17="?",ROUND(AVERAGE($B$2:$B$2344),0),B17) -> 1996 | O17: =IF(C17="?","Sep",C17) -> Oct | P17: =IF(G17="?",$K$5,G17) -> tier - 3 | Q17: =IF(H17="?",$M$5,H17) -> tier - 3 | R17: =IF(I17="?","Unknown",I17) -> R1013 | S17: =IFERROR(DATE(N17,MONTH(DATEVALUE(O17&"-1")),D17),"") -> 35360 | T17: =IFERROR(DATEDIF(S17,DATE(2023,6,8),"y"),"") -> 26
... A1050: Id1290 | B1050: 1977 | C1050: Jul | D1050: 26 | E1050: 2 | F1050: 8527.53 | G1050: tier - 2 | H1050: tier - 2 | I1050: R1013 | N1050: =IF(B1050="?",ROUND(AVERAGE($B$2:$B$2344),0),B1050) -> 1977 | O1050: =IF(C1050="?","Sep",C1050) -> Jul | P1050: =IF(G1050="?",$K$5,G1050) -> tier - 2 | Q1050: =IF(H1050="?",$M$5,H1050) -> tier - 2 | R1050: =IF(I1050="?","Unknown",I1050) -> R1013 | S1050: =IFERROR(DATE(N1050,MONTH(DATEVALUE(O1050&"-1")),D1050),"") -> 28332 | T1050: =IFERROR(DATEDIF(S1050,DATE(2023,6,8),"y"),"") -> 45
A1051: Id1289 | B1051: ? | C1051: Jul | D1051: 24 | E1051: 0 | F1051: 8534.67 | G1051: tier - 2 | H1051: tier - 3 | I1051: R1024 | N1051: =IF(B1051="?",ROUND(AVERAGE($B$2:$B$2344),0),B1051) -> 1983 | O1051: =IF(C1051="?","Sep",C1051) -> Jul | P1051: =IF(G1051="?",$K$5,G1051) -> tier - 2 | Q1051: =IF(H1051="?",$M$5,H1051) -> tier - 3 | R1051: =IF(I1051="?","Unknown",I1051) -> R1024 | S1051: =IFERROR(DATE(N1051,MONTH(DATEVALUE(O1051&"-1")),D1051),"") -> 30521 | T1051: =IFERROR(DATEDIF(S1051,DATE(2023,6,8),"y"),"") -> 39
A1052: Id1288 | B1052: 1981 | C1052: Dec | D1052: 27 | E1052: 3 | F1052: 8538.29 | G1052: tier - 2 | H1052: tier - 3 | I1052: R1024 | N1052: =IF(B1052="?",ROUND(AVERAGE($B$2:$B$2344),0),B1052) -> 1981 | O1052: =IF(C1052="?","Sep",C1052) -> Dec | P1052: =IF(G1052="?",$K$5,G1052) -> tier - 2 | Q1052: =IF(H1052="?",$M$5,H1052) -> tier - 3 | R1052: =IF(I1052="?","Unknown",I1052) -> R1024 | S1052: =IFERROR(DATE(N1052,MONTH(DATEVALUE(O1052&"-1")),D1052),"") -> 29947 | T1052: =IFERROR(DATEDIF(S1052,DATE(2023,6,8),"y"),"") -> 41
A1053: Id1287 | B1053: 1975 | C1053: Nov | D1053: 6 | E1053: 1 | F1053: 8539.67 | G1053: tier - 2 | H1053: tier - 3 | I1053: R1011 | N1053: =IF(B1053="?",ROUND(AVERAGE($B$2:$B$2344),0),B1053) -> 1975 | O1053: =IF(C1053="?","Sep",C1053) -> Nov | P1053: =IF(G1053="?",$K$5,G1053) -> tier - 2 | Q1053: =IF(H1053="?",$M$5,H1053) -> tier - 3 | R1053: =IF(I1053="?","Unknown",I1053) -> R1011 | S1053: =IFERROR(DATE(N1053,MONTH(DATEVALUE(O1053&"-1")),D1053),"") -> 27704 | T1053: =IFERROR(DATEDIF(S1053,DATE(2023,6,8),"y"),"") -> 47
A1054: Id1286 | B1054: ? | C1054: Dec | D1054: 12 | E1054: 1 | F1054: 8547.69 | G1054: tier - 2 | H1054: tier - 1 | I1054: R1013 | N1054: =IF(B1054="?",ROUND(AVERAGE($B$2:$B$2344),0),B1054) -> 1983 | O1054: =IF(C1054="?","Sep",C1054) -> Dec | P1054: =IF(G1054="?",$K$5,G1054) -> tier - 2 | Q1054: =IF(H1054="?",$M$5,H1054) -> tier - 1 | R1054: =IF(I1054="?","Unknown",I1054) -> R1013 | S1054: =IFERROR(DATE(N1054,MONTH(DATEVALUE(O1054&"-1")),D1054),"") -> 30662 | T1054: =IFERROR(DATEDIF(S1054,DATE(2023,6,8),"y"),"") -> 39
A1055: Id1285 | B1055: 1975 | C1055: Aug | D1055: 6 | E1055: 1 | F1055: 8551.35 | G1055: tier - 2 | H1055: tier - 2 | I1055: R1011 | N1055: =IF(B1055="?",ROUND(AVERAGE($B$2:$B$2344),0),B1055) -> 1975 | O1055: =IF(C1055="?","Sep",C1055) -> Aug | P1055: =IF(G1055="?",$K$5,G1055) -> tier - 2 | Q1055: =IF(H1055="?",$M$5,H1055) -> tier - 2 | R1055: =IF(I1055="?","Unknown",I1055) -> R1011 | S1055: =IFERROR(DATE(N1055,MONTH(DATEVALUE(O1055&"-1")),D1055),"") -> 27612 | T1055: =IFERROR(DATEDIF(S1055,DATE(2023,6,8),"y"),"") -> 47
A1056: Id1284 | B1056: 1975 | C1056: Aug | D1056: 21 | E1056: 1 | F1056: 8556.91 | G1056: tier - 2 | H1056: tier - 1 | I1056: R1011 | N1056: =IF(B1056="?",ROUND(AVERAGE($B$2:$B$2344),0),B1056) -> 1975 | O1056: =IF(C1056="?","Sep",C1056) -> Aug | P1056: =IF(G1056="?",$K$5,G1056) -> tier - 2 | Q1056: =IF(H1056="?",$M$5,H1056) -> tier - 1 | R1056: =IF(I1056="?","Unknown",I1056) -> R1011 | S1056: =IFERROR(DATE(N1056,MONTH(DATEVALUE(O1056&"-1")),D1056),"") -> 27627 | T1056: =IFERROR(DATEDIF(S1056,DATE(2023,6,8),"y"),"") -> 47
A1057: Id1283 | B1057: 1988 | C1057: Sep | D1057: 21 | E1057: 3 | F1057: 8567.25 | G1057: tier - 2 | H1057: tier - 1 | I1057: R1012 | N1057: =IF(B1057="?",ROUND(AVERAGE($B$2:$B$2344),0),B1057) -> 1988 | O1057: =IF(C1057="?","Sep",C1057) -> Sep | P1057: =IF(G1057="?",$K$5,G1057) -> tier - 2 | Q1057: =IF(H1057="?",$M$5,H1057) -> tier - 1 | R1057: =IF(I1057="?","Unknown",I1057) -> R1012 | S1057: =IFERROR(DATE(N1057,MONTH(DATEVALUE(O1057&"-1")),D1057),"") -> 32407 | T1057: =IFERROR(DATEDIF(S1057,DATE(2023,6,8),"y"),"") -> 34
A1058: Id1282 | B1058: 1975 | C1058: Sep | D1058: 26 | E1058: 1 | F1058: 8569.86 | G1058: tier - 2 | H1058: tier - 3 | I1058: R1013 | N1058: =IF(B1058="?",ROUND(AVERAGE($B$2:$B$2344),0),B1058) -> 1975 | O1058: =IF(C1058="?","Sep",C1058) -> Sep | P1058: =IF(G1058="?",$K$5,G1058) -> tier - 2 | Q1058: =IF(H1058="?",$M$5,H1058) -> tier - 3 | R1058: =IF(I1058="?","Unknown",I1058) -> R1013 | S1058: =IFERROR(DATE(N1058,MONTH(DATEVALUE(O1058&"-1")),D1058),"") -> 27663 | T1058: =IFERROR(DATEDIF(S1058,DATE(2023,6,8),"y"),"") -> 47
A1059: Id1281 | B1059: 1982 | C1059: Dec | D1059: 6 | E1059: 3 | F1059: 8572.04 | G1059: tier - 2 | H1059: tier - 2 | I1059: R1021 | N1059: =IF(B1059="?",ROUND(AVERAGE($B$2:$B$2344),0),B1059) -> 1982 | O1059: =IF(C1059="?","Sep",C1059) -> Dec | P1059: =IF(G1059="?",$K$5,G1059) -> tier - 2 | Q1059: =IF(H1059="?",$M$5,H1059) -> tier - 2 | R1059: =IF(I1059="?","Unknown",I1059) -> R1021 | S1059: =IFERROR(DATE(N1059,MONTH(DATEVALUE(O1059&"-1")),D1059),"") -> 30291 | T1059: =IFERROR(DATEDIF(S1059,DATE(2023,6,8),"y"),"") -> 40
A1060: Id1280 | B1060: 1987 | C1060: Nov | D1060: 11 | E1060: 3 | F1060: 8573.3 | G1060: tier - 2 | H1060: tier - 2 | I1060: R1021 | N1060: =IF(B1060="?",ROUND(AVERAGE($B$2:$B$2344),0),B1060) -> 1987 | O1060: =IF(C1060="?","Sep",C1060) -> Nov | P1060: =IF(G1060="?",$K$5,G1060) -> tier - 2 | Q1060: =IF(H1060="?",$M$5,H1060) -> tier - 2 | R1060: =IF(I1060="?","Unknown",I1060) -> R1021 | S1060: =IFERROR(DATE(N1060,MONTH(DATEVALUE(O1060&"-1")),D1060),"") -> 32092 | T1060: =IFERROR(DATEDIF(S1060,DATE(2023,6,8),"y"),"") -> 35
A1061: Id1279 | B1061: 1983 | C1061: Dec | D1061: 30 | E1061: 5 | F1061: 8582.3 | G1061: tier - 2 | H1061: tier - 1 | I1061: R1013 | N1061: =IF(B1061="?",ROUND(AVERAGE($B$2:$B$2344),0),B1061) -> 1983 | O1061: =IF(C1061="?","Sep",C1061) -> Dec | P1061: =IF(G1061="?",$K$5,G1061) -> tier - 2 | Q1061: =IF(H1061="?",$M$5,H1061) -> tier - 1 | R1061: =IF(I1061="?","Unknown",I1061) -> R1013 | S1061: =IFERROR(DATE(N1061,MONTH(DATEVALUE(O1061&"-1")),D1061),"") -> 30680 | T1061: =IFERROR(DATEDIF(S1061,DATE(2023,6,8),"y"),"") -> 39
A1062: Id1278 | B1062: 1983 | C1062: Jul | D1062: 25 | E1062: 5 | F1062: 8596.83 | G1062: tier - 2 | H1062: tier - 3 | I1062: R1013 | N1062: =IF(B1062="?",ROUND(AVERAGE($B$2:$B$2344),0),B1062) -> 1983 | O1062: =IF(C1062="?","Sep",C1062) -> Jul | P1062: =IF(G1062="?",$K$5,G1062) -> tier - 2 | Q1062: =IF(H1062="?",$M$5,H1062) -> tier - 3 | R1062: =IF(I1062="?","Unknown",I1062) -> R1013 | S1062: =IFERROR(DATE(N1062,MONTH(DATEVALUE(O1062&"-1")),D1062),"") -> 30522 | T1062: =IFERROR(DATEDIF(S1062,DATE(2023,6,8),"y"),"") -> 39
A1063: Id1277 | B1063: 1973 | C1063: Jul | D1063: 11 | E1063: 0 | F1063: 8601.33 | G1063: tier - 2 | H1063: tier - 1 | I1063: R1013 | N1063: =IF(B1063="?",ROUND(AVERAGE($B$2:$B$2344),0),B1063) -> 1973 | O1063: =IF(C1063="?","Sep",C1063) -> Jul | P1063: =IF(G1063="?",$K$5,G1063) -> tier - 2 | Q1063: =IF(H1063="?",$M$5,H1063) -> tier - 1 | R1063: =IF(I1063="?","Unknown",I1063) -> R1013 | S1063: =IFERROR(DATE(N1063,MONTH(DATEVALUE(O1063&"-1")),D1063),"") -> 26856 | T1063: =IFERROR(DATEDIF(S1063,DATE(2023,6,8),"y"),"") -> 49
A1064: Id1276 | B1064: 1977 | C1064: Sep | D1064: 24 | E1064: 2 | F1064: 8603.82 | G1064: tier - 2 | H1064: tier - 1 | I1064: R1019 | N1064: =IF(B1064="?",ROUND(AVERAGE($B$2:$B$2344),0),B1064) -> 1977 | O1064: =IF(C1064="?","Sep",C1064) -> Sep | P1064: =IF(G1064="?",$K$5,G1064) -> tier - 2 | Q1064: =IF(H1064="?",$M$5,H1064) -> tier - 1 | R1064: =IF(I1064="?","Unknown",I1064) -> R1019 | S1064: =IFERROR(DATE(N1064,MONTH(DATEVALUE(O1064&"-1")),D1064),"") -> 28392 | T1064: =IFERROR(DATEDIF(S1064,DATE(2023,6,8),"y"),"") -> 45
A1065: Id1275 | B1065: 1977 | C1065: Nov | D1065: 12 | E1065: 2 | F1065: 8604.48 | G1065: tier - 3 | H1065: tier - 2 | I1065: R1016 | N1065: =IF(B1065="?",ROUND(AVERAGE($B$2:$B$2344),0),B1065) -> 1977 | O1065: =IF(C1065="?","Sep",C1065) -> Nov | P1065: =IF(G1065="?",$K$5,G1065) -> tier - 3 | Q1065: =IF(H1065="?",$M$5,H1065) -> tier - 2 | R1065: =IF(I1065="?","Unknown",I1065) -> R1016 | S1065: =IFERROR(DATE(N1065,MONTH(DATEVALUE(O1065&"-1")),D1065),"") -> 28441 | T1065: =IFERROR(DATEDIF(S1065,DATE(2023,6,8),"y"),"") -> 45
A1066: Id1274 | B1066: 1977 | C1066: Oct | D1066: 15 | E1066: 3 | F1066: 8605.36 | G1066: tier - 2 | H1066: tier - 2 | I1066: R1013 | N1066: =IF(B1066="?",ROUND(AVERAGE($B$2:$B$2344),0),B1066) -> 1977 | O1066: =IF(C1066="?","Sep",C1066) -> Oct | P1066: =IF(G1066="?",$K$5,G1066) -> tier - 2 | Q1066: =IF(H1066="?",$M$5,H1066) -> tier - 2 | R1066: =IF(I1066="?","Unknown",I1066) -> R1013 | S1066: =IFERROR(DATE(N1066,MONTH(DATEVALUE(O1066&"-1")),D1066),"") -> 28413 | T1066: =IFERROR(DATEDIF(S1066,DATE(2023,6,8),"y"),"") -> 45
... A2344: Id1 | B2344: 1968 | C2344: Oct | D2344: 12 | E2344: 0 | F2344: 63770.43 | G2344: tier - 1 | H2344: tier - 3 | I2344: R1013 | N2344: =IF(B2344="?",ROUND(AVERAGE($B$2:$B$2344),0),B2344) -> 1968 | O2344: =IF(C2344="?","Sep",C2344) -> Oct | P2344: =IF(G2344="?",$K$5,G2344) -> tier - 1 | Q2344: =IF(H2344="?",$M$5,H2344) -> tier - 3 | R2344: =IF(I2344="?","Unknown",I2344) -> R1013 | S2344: =IFERROR(DATE(N2344,MONTH(DATEVALUE(O2344&"-1")),D2344),"") -> 25123 | T2344: =IFERROR(DATEDIF(S2344,DATE(2023,6,8),"y"),"") -> 54

Sheet Healthcare
A1: Customer ID | B1: First Name | C1: BMI | D1: HBA1C | E1: Heart Issues | F1: Any Transplants | G1: Cancer History | H1: Number of Major Surgeries | I1: Smoker | J1: Weight Status | K1: Diabetes Status | L1: Date of Birth | M1: Charges | N1: Hospital Tier | O1: City Tier | P1: State ID | Q1: Age
A2: ='Customer Names'!A2 -> Id1 | B2: =IFERROR(INDEX('Customer Names'!$D:$D,MATCH($A2,'Customer Names'!$A:$A,0)),"Not Found") -> Kelly | C2: =IFERROR(INDEX('Medical Examinations'!$B:$B,MATCH($A2,'Medical Examinations'!$A:$A,0)),"Not Found") -> 47.41 | D2: =IFERROR(INDEX('Medical Examinations'!$C:$C,MATCH($A2,'Medical Examinations'!$A:$A,0)),"Not Found") -> 7.47 | E2: =IFERROR(INDEX('Medical Examinations'!$I:$I,MATCH($A2,'Medical Examinations'!$A:$A,0)),"Not Found") -> No | F2: =IFERROR(INDEX('Medical Examinations'!$J:$J,MATCH($A2,'Medical Examinations'!$A:$A,0)),"Not Found") -> No | G2: =IFERROR(INDEX('Medical Examinations'!$F:$F,MATCH($A2,'Medical Examinations'!$A:$A,0)),"Not Found") -> No | H2: =IFERROR(INDEX('Medical Examinations'!$L:$L,MATCH($A2,'Medical Examinations'!$A:$A,0)),"Not Found") -> 0 | I2: =IFERROR(INDEX('Medical Examinations'!$K:$K,MATCH($A2,'Medical Examinations'!$A:$A,0)),"Not Found") -> Yes | J2: =IFERROR(INDEX('Medical Examinations'!$M:$M,MATCH($A2,'Medical Examinations'!$A:$A,0)),"Not Found") -> Obesity | K2: =IFERROR(INDEX('Medical Examinations'!$N:$N,MATCH($A2,'Medical Examinations'!$A:$A,0)),"Not Found") -> Diabetic | L2: =IFERROR(INDEX('Hospitalisation Details'!$V:$V,MATCH($A2,'Hospitalisation Details'!$A:$A,0)),"Not Found") -> 0 | M2: =IFERROR(INDEX('Hospitalisation Details'!$F:$F,MATCH($A2,'Hospitalisation Details'!$A:$A,0)),"Not Found") -> 63770.43 | N2: =IFERROR(INDEX('Hospitalisation Details'!$S:$S,MATCH($A2,'Hospitalisation Details'!$A:$A,0)),"Not Found") -> 25123 | O2: =IFERROR(INDEX('Hospitalisation Details'!$T:$T,MATCH($A2,'Hospitalisation Details'!$A:$A,0)),"Not Found") -> 54 | P2: =IFERROR(INDEX('Hospitalisation Details'!$U:$U,MATCH($A2,'Hospitalisation Details'!$A:$A,0)),"Not Found") -> 0 | Q2: =IFERROR(INDEX('Hospitalisation Details'!$W:$W,MATCH($A2,'Hospitalisation Details'!$A:$A,0)),"Not Found") -> 0
A3: ='Customer Names'!A3 -> Id2 | B3: =IFERROR(INDEX('Customer Names'!$D:$D,MATCH($A3,'Customer Names'!$A:$A,0)),"Not Found") -> Matthew D | C3: =IFERROR(INDEX('Medical Examinations'!$B:$B,MATCH($A3,'Medical Examinations'!$A:$A,0)),"Not Found") -> 30.36 | D3: =IFERROR(INDEX('Medical Examinations'!$C:$C,MATCH($A3,'Medical Examinations'!$A:$A,0)),"Not Found") -> 5.77 | E3: =IFERROR(INDEX('Medical Examinations'!$I:$I,MATCH($A3,'Medical Examinations'!$A:$A,0)),"Not Found") -> No | F3: =IFERROR(INDEX('Medical Examinations'!$J:$J,MATCH($A3,'Medical Examinations'!$A:$A,0)),"Not Found") -> No | G3: =IFERROR(INDEX('Medical Examinations'!$F:$F,MATCH($A3,'Medical Examinations'!$A:$A,0)),"Not Found") -> No | H3: =IFERROR(INDEX('Medical Examinations'!$L:$L,MATCH($A3,'Medical Examinations'!$A:$A,0)),"Not Found") -> 0 | I3: =IFERROR(INDEX('Medical Examinations'!$K:$K,MATCH($A3,'Medical Examinations'!$A:$A,0)),"Not Found") -> Yes | J3: =IFERROR(INDEX('Medical Examinations'!$M:$M,MATCH($A3,'Medical Examinations'!$A:$A,0)),"Not Found") -> Obesity | K3: =IFERROR(INDEX('Medical Examinations'!$N:$N,MATCH($A3,'Medical Examinations'!$A:$A,0)),"Not Found") -> Prediabetic | L3: =IFERROR(INDEX('Hospitalisation Details'!$V:$V,MATCH($A3,'Hospitalisation Details'!$A:$A,0)),"Not Found") -> 0 | M3: =IFERROR(INDEX('Hospitalisation Details'!$F:$F,MATCH($A3,'Hospitalisation Details'!$A:$A,0)),"Not Found") -> 62592.87 | N3: =IFERROR(INDEX('Hospitalisation Details'!$S:$S,MATCH($A3,'Hospitalisation Details'!$A:$A,0)),"Not Found") -> 28284 | O3: =IFERROR(INDEX('Hospitalisation Details'!$T:$T,MATCH($A3,'Hospitalisation Details'!$A:$A,0)),"Not Found") -> 46 | P3: =IFERROR(INDEX('Hospitalisation Details'!$U:$U,MATCH($A3,'Hospitalisation Details'!$A:$A,0)),"Not Found") -> 0 | Q3: =IFERROR(INDEX('Hospitalisation Details'!$W:$W,MATCH($A3,'Hospitalisation Details'!$A:$A,0)),"Not Found") -> 0
A4: ='Customer Names'!A4 -> Id3 | B4: =IFERROR(INDEX('Customer Names'!$D:$D,MATCH($A4,'Customer Names'!$A:$A,0)),"Not Found") -> Phil | C4: =IFERROR(INDEX('Medical Examinations'!$B:$B,MATCH($A4,'Medical Examinations'!$A:$A,0)),"Not Found") -> 34.485 | D4: =IFERROR(INDEX('Medical Examinations'!$C:$C,MATCH($A4,'Medical Examinations'!$A:$A,0)),"Not Found") -> 11.87 | E4: =IFERROR(INDEX('Medical Examinations'!$I:$I,MATCH($A4,'Medical Examinations'!$A:$A,0)),"Not Found") -> Yes | F4: =IFERROR(INDEX('Medical Examinations'!$J:$J,MATCH($A4,'Medical Examinations'!$A:$A,0)),"Not Found") -> No | G4: =IFERROR(INDEX('Medical Examinations'!$F:$F,MATCH($A4,'Medical Examinations'!$A:$A,0)),"Not Found") -> No | H4: =IFERROR(INDEX('Medical Examinations'!$L:$L,MATCH($A4,'Medical Examinations'!$A:$A,0)),"Not Found") -> 2 | I4: =IFERROR(INDEX('Medical Examinations'!$K:$K,MATCH($A4,'Medical Examinations'!$A:$A,0)),"Not Found") -> Yes | J4: =IFERROR(INDEX('Medical Examinations'!$M:$M,MATCH($A4,'Medical Examinations'!$A:$A,0)),"Not Found") -> Obesity | K4: =IFERROR(INDEX('Medical Examinations'!$N:$N,MATCH($A4,'Medical Examinations'!$A:$A,0)),"Not Found") -> Diabetic | L4: =IFERROR(INDEX('Hospitalisation Details'!$V:$V,MATCH($A4,'Hospitalisation Details'!$A:$A,0)),"Not Found") -> 0 | M4: =IFERROR(INDEX('Hospitalisation Details'!$F:$F,MATCH($A4,'Hospitalisation Details'!$A:$A,0)),"Not Found") -> 60021.4 | N4: =IFERROR(INDEX('Hospitalisation Details'!$S:$S,MATCH($A4,'Hospitalisation Details'!$A:$A,0)),"Not Found") -> 25822 | O4: =IFERROR(INDEX('Hospitalisation Details'!$T:$T,MATCH($A4,'Hospitalisation Details'!$A:$A,0)),"Not Found") -> 52 | P4: =IFERROR(INDEX('Hospitalisation Details'!$U:$U,MATCH($A4,'Hospitalisation Details'!$A:$A,0)),"Not Found") -> 0 | Q4: =IFERROR(INDEX('Hospitalisation Details'!$W:$W,MATCH($A4,'Hospitalisation Details'!$A:$A,0)),"Not Found") -> 0
A5: ='Customer Names'!A5 -> Id4 | B5: =IFERROR(INDEX('Customer Names'!$D:$D,MATCH($A5,'Customer Names'!$A:$A,0)),"Not Found") -> Kelsey | C5: =IFERROR(INDEX('Medical Examinations'!$B:$B,MATCH($A5,'Medical Examinations'!$A:$A,0)),"Not Found") -> 38.095 | D5: =IFERROR(INDEX('Medical Examinations'!$C:$C,MATCH($A5,'Medical Examinations'!$A:$A,0)),"Not Found") -> 6.05 | E5: =IFERROR(INDEX('Medical Examinations'!$I:$I,MATCH($A5,'Medical Examinations'!$A:$A,0)),"Not Found") -> No | F5: =IFERROR(INDEX('Medical Examinations'!$J:$J,MATCH($A5,'Medical Examinations'!$A:$A,0)),"Not Found") -> No | G5: =IFERROR(INDEX('Medical Examinations'!$F:$F,MATCH($A5,'Medical Examinations'!$A:$A,0)),"Not Found") -> No | H5: =IFERROR(INDEX('Medical Examinations'!$L:$L,MATCH($A5,'Medical Examinations'!$A:$A,0)),"Not Found") -> 0 | I5: =IFERROR(INDEX('Medical Examinations'!$K:$K,MATCH($A5,'Medical Examinations'!$A:$A,0)),"Not Found") -> Yes | J5: =IFERROR(INDEX('Medical Examinations'!$M:$M,MATCH($A5,'Medical Examinations'!$A:$A,0)),"Not Found") -> Obesity | K5: =IFERROR(INDEX('Medical Examinations'!$N:$N,MATCH($A5,'Medical Examinations'!$A:$A,0)),"Not Found") -> Prediabetic | L5: =IFERROR(INDEX('Hospitalisation Details'!$V:$V,MATCH($A5,'Hospitalisation Details'!$A:$A,0)),"Not Found") -> 0 | M5: =IFERROR(INDEX('Hospitalisation Details'!$F:$F,MATCH($A5,'Hospitalisation Details'!$A:$A,0)),"Not Found") -> 58571.07 | N5: =IFERROR(INDEX('Hospitalisation Details'!$S:$S,MATCH($A5,'Hospitalisation Details'!$A:$A,0)),"Not Found") -> 33395 | O5: =IFERROR(INDEX('Hospitalisation Details'!$T:$T,MATCH($A5,'Hospitalisation Details'!$A:$A,0)),"Not Found") -> 32 | P5: =IFERROR(INDEX('Hospitalisation Details'!$U:$U,MATCH($A5,'Hospitalisation Details'!$A:$A,0)),"Not Found") -> 0 | Q5: =IFERROR(INDEX('Hospitalisation Details'!$W:$W,MATCH($A5,'Hospitalisation Details'!$A:$A,0)),"Not Found") -> 0
A6: ='Customer Names'!A6 -> Id5 | B6: =IFERROR(INDEX('Customer Names'!$D:$D,MATCH($A6,'Customer Names'!$A:$A,0)),"Not Found") -> Kristyn | C6: =IFERROR(INDEX('Medical Examinations'!$B:$B,MATCH($A6,'Medical Examinations'!$A:$A,0)),"Not Found") -> 35.53 | D6: =IFERROR(INDEX('Medical Examinations'!$C:$C,MATCH($A6,'Medical Examinations'!$A:$A,0)),"Not Found") -> 5.45 | E6: =IFERROR(INDEX('Medical Examinations'!$I:$I,MATCH($A6,'Medical Examinations'!$A:$A,0)),"Not Found") -> No | F6: =IFERROR(INDEX('Medical Examinations'!$J:$J,MATCH($A6,'Medical Examinations'!$A:$A,0)),"Not Found") -> No | G6: =IFERROR(INDEX('Medical Examinations'!$F:$F,MATCH($A6,'Medical Examinations'!$A:$A,0)),"Not Found") -> No | H6: =IFERROR(INDEX('Medical Examinations'!$L:$L,MATCH($A6,'Medical Examinations'!$A:$A,0)),"Not Found") -> 0 | I6: =IFERROR(INDEX('Medical Examinations'!$K:$K,MATCH($A6,'Medical Examinations'!$A:$A,0)),"Not Found") -> Yes | J6: =IFERROR(INDEX('Medical Examinations'!$M:$M,MATCH($A6,'Medical Examinations'!$A:$A,0)),"Not Found") -> Obesity | K6: =IFERROR(INDEX('Medical Examinations'!$N:$N,MATCH($A6,'Medical Examinations'!$A:$A,0)),"Not Found") -> Normal | L6: =IFERROR(INDEX('Hospitalisation Details'!$V:$V,MATCH($A6,'Hospitalisation Details'!$A:$A,0)),"Not Found") -> 0 | M6: =IFERROR(INDEX('Hospitalisation Details'!$F:$F,MATCH($A6,'Hospitalisation Details'!$A:$A,0)),"Not Found") -> 55135.4 | N6: =IFERROR(INDEX('Hospitalisation Details'!$S:$S,MATCH($A6,'Hospitalisation Details'!$A:$A,0)),"Not Found") -> 32678 | O6: =IFERROR(INDEX('Hospitalisation Details'!$T:$T,MATCH($A6,'Hospitalisation Details'!$A:$A,0)),"Not Found") -> 33 | P6: =IFERROR(INDEX('Hospitalisation Details'!$U:$U,MATCH($A6,'Hospitalisation Details'!$A:$A,0)),"Not Found") -> 0 | Q6: =IFERROR(INDEX('Hospitalisation Details'!$W:$W,MATCH($A6,'Hospitalisation Details'!$A:$A,0)),"Not Found") -> 0
A7: ='Customer Names'!A7 -> Id6 | B7: =IFERROR(INDEX('Customer Names'!$D:$D,MATCH($A7,'Customer Names'!$A:$A,0)),"Not Found") -> Russell B. | C7: =IFERROR(INDEX('Medical Examinations'!$B:$B,MATCH($A7,'Medical Examinations'!$A:$A,0)),"Not Found") -> 32.8 | D7: =IFERROR(INDEX('Medical Examinations'!$C:$C,MATCH($A7,'Medical Examinations'!$A:$A,0)),"Not Found") -> 6.59 | E7: =IFERROR(INDEX('Medical Examinations'!$I:$I,MATCH($A7,'Medical Examinations'!$A:$A,0)),"Not Found") -> No | F7: =IFERROR(INDEX('Medical Examinations'!$J:$J,MATCH($A7,'Medical Examinations'!$A:$A,0)),"Not Found") -> No | G7: =IFERROR(INDEX('Medical Examinations'!$F:$F,MATCH($A7,'Medical Examinations'!$A:$A,0)),"Not Found") -> No | H7: =IFERROR(INDEX('Medical Examinations'!$L:$L,MATCH($A7,'Medical Examinations'!$A:$A,0)),"Not Found") -> 0 | I7: =IFERROR(INDEX('Medical Examinations'!$K:$K,MATCH($A7,'Medical Examinations'!$A:$A,0)),"Not Found") -> Yes | J7: =IFERROR(INDEX('Medical Examinations'!$M:$M,MATCH($A7,'Medical Examinations'!$A:$A,0)),"Not Found") -> Obesity | K7: =IFERROR(INDEX('Medical Examinations'!$N:$N,MATCH($A7,'Medical Examinations'!$A:$A,0)),"Not Found") -> Diabetic | L7: =IFERROR(INDEX('Hospitalisation Details'!$V:$V,MATCH($A7,'Hospitalisation Details'!$A:$A,0)),"Not Found") -> 0 | M7: =IFERROR(INDEX('Hospitalisation Details'!$F:$F,MATCH($A7,'Hospitalisation Details'!$A:$A,0)),"Not Found") -> 52590.83 | N7: =IFERROR(INDEX('Hospitalisation Details'!$S:$S,MATCH($A7,'Hospitalisation Details'!$A:$A,0)),"Not Found") -> 22862 | O7: =IFERROR(INDEX('Hospitalisation Details'!$T:$T,MATCH($A7,'Hospitalisation Details'!$A:$A,0)),"Not Found") -> 60 | P7: =IFERROR(INDEX('Hospitalisation Details'!$U:$U,MATCH($A7,'Hospitalisation Details'!$A:$A,0)),"Not Found") -> 0 | Q7: =IFERROR(INDEX('Hospitalisation Details'!$W:$W,MATCH($A7,'Hospitalisation Details'!$A:$A,0)),"Not Found") -> 0
A8: ='Customer Names'!A8 -> Id7 | B8: =IFERROR(INDEX('Customer Names'!$D:$D,MATCH($A8,'Customer Names'!$A:$A,0)),"Not Found") -> Scott | C8: =IFERROR(INDEX('Medical Examinations'!$B:$B,MATCH($A8,'Medical Examinations'!$A:$A,0)),"Not Found") -> 36.4 | D8: =IFERROR(INDEX('Medical Examinations'!$C:$C,MATCH($A8,'Medical Examinations'!$A:$A,0)),"Not Found") -> 6.07 | E8: =IFERROR(INDEX('Medical Examinations'!$I:$I,MATCH($A8,'Medical Examinations'!$A:$A,0)),"Not Found") -> No | F8: =IFERROR(INDEX('Medical Examinations'!$J:$J,MATCH($A8,'Medical Examinations'!$A:$A,0)),"Not Found") -> No | G8: =IFERROR(INDEX('Medical Examinations'!$F:$F,MATCH($A8,'Medical Examinations'!$A:$A,0)),"Not Found") -> No | H8: =IFERROR(INDEX('Medical Examinations'!$L:$L,MATCH($A8,'Medical Examinations'!$A:$A,0)),"Not Found") -> 0 | I8: =IFERROR(INDEX('Medical Examinations'!$K:$K,MATCH($A8,'Medical Examinations'!$A:$A,0)),"Not Found") -> Yes | J8: =IFERROR(INDEX('Medical Examinations'!$M:$M,MATCH($A8,'Medical Examinations'!$A:$A,0)),"Not Found") -> Obesity | K8: =IFERROR(INDEX('Medical Examinations'!$N:$N,MATCH($A8,'Medical Examinations'!$A:$A,0)),"Not Found") -> Prediabetic | L8: =IFERROR(INDEX('Hospitalisation Details'!$V:$V,MATCH($A8,'Hospitalisation Details'!$A:$A,0)),"Not Found") -> 0 | M8: =IFERROR(INDEX('Hospitalisation Details'!$F:$F,MATCH($A8,'Hospitalisation Details'!$A:$A,0)),"Not Found") -> 51194.56 | N8: =IFERROR(INDEX('Hospitalisation Details'!$S:$S,MATCH($A8,'Hospitalisation Details'!$A:$A,0)),"Not Found") -> 34634 | O8: =IFERROR(INDEX('Hospitalisation Details'!$T:$T,MATCH($A8,'Hospitalisation Details'!$A:$A,0)),"Not Found") -> 28 | P8: =IFERROR(INDEX('Hospitalisation Details'!$U:$U,MATCH($A8,'Hospitalisation Details'!$A:$A,0)),"Not Found") -> 0 | Q8: =IFERROR(INDEX('Hospitalisation Details'!$W:$W,MATCH($A8,'Hospitalisation Details'!$A:$A,0)),"Not Found") -> 0
A9: ='Customer Names'!A9 -> Id8 | B9: =IFERROR(INDEX('Customer Names'!$D:$D,MATCH($A9,'Customer Names'!$A:$A,0)),"Not Found") -> Stephen | C9: =IFERROR(INDEX('Medical Examinations'!$B:$B,MATCH($A9,'Medical Examinations'!$A:$A,0)),"Not Found") -> 36.96 | D9: =IFERROR(INDEX('Medical Examinations'!$C:$C,MATCH($A9,'Medical Examinations'!$A:$A,0)),"Not Found") -> 7.93 | E9: =IFERROR(INDEX('Medical Examinations'!$I:$I,MATCH($A9,'Medical Examinations'!$A:$A,0)),"Not Found") -> No | F9: =IFERROR(INDEX('Medical Examinations'!$J:$J,MATCH($A9,'Medical Examinations'!$A:$A,0)),"Not Found") -> No | G9: =IFERROR(INDEX('Medical Examinations'!$F:$F,MATCH($A9,'Medical Examinations'!$A:$A,0)),"Not Found") -> No | H9: =IFERROR(INDEX('Medical Examinations'!$L:$L,MATCH($A9,'Medical Examinations'!$A:$A,0)),"Not Found") -> 3 | I9: =IFERROR(INDEX('Medical Examinations'!$K:$K,MATCH($A9,'Medical Examinations'!$A:$A,0)),"Not Found") -> Yes | J9: =IFERROR(INDEX('Medical Examinations'!$M:$M,MATCH($A9,'Medical Examinations'!$A:$A,0)),"Not Found") -> Obesity | K9: =IFERROR(INDEX('Medical Examinations'!$N:$N,MATCH($A9,'Medical Examinations'!$A:$A,0)),"Not Found") -> Diabetic | L9: =IFERROR(INDEX('Hospitalisation Details'!$V:$V,MATCH($A9,'Hospitalisation Details'!$A:$A,0)),"Not Found") -> 0 | M9: =IFERROR(INDEX('Hospitalisation Details'!$F:$F,MATCH($A9,'Hospitalisation Details'!$A:$A,0)),"Not Found") -> 49577.66 | N9: =IFERROR(INDEX('Hospitalisation Details'!$S:$S,MATCH($A9,'Hospitalisation Details'!$A:$A,0)),"Not Found") -> 21363 | O9: =IFERROR(INDEX('Hospitalisation Details'!$T:$T,MATCH($A9,'Hospitalisation Details'!$A:$A,0)),"Not Found") -> 64 | P9: =IFERROR(INDEX('Hospitalisation Details'!$U:$U,MATCH($A9,'Hospitalisation Details'!$A:$A,0)),"Not Found") -> 0 | Q9: =IFERROR(INDEX('Hospitalisation Details'!$W:$W,MATCH($A9,'Hospitalisation Details'!$A:$A,0)),"Not Found") -> 0
A10: ='Customer Names'!A10 -> Id9 | B10: =IFERROR(INDEX('Customer Names'!$D:$D,MATCH($A10,'Customer Names'!$A:$A,0)),"Not Found") -> Patrick R. | C10: =IFERROR(INDEX('Medical Examinations'!$B:$B,MATCH($A10,'Medical Examinations'!$A:$A,0)),"Not Found") -> 41.14 | D10: =IFERROR(INDEX('Medical Examinations'!$C:$C,MATCH($A10,'Medical Examinations'!$A:$A,0)),"Not Found") -> 9.58 | E10: =IFERROR(INDEX('Medical Examinations'!$I:$I,MATCH($A10,'Medical Examinations'!$A:$A,0)),"Not Found") -> Yes | F10: =IFERROR(INDEX('Medical Examinations'!$J:$J,MATCH($A10,'Medical Examinations'!$A:$A,0)),"Not Found") -> No | G10: =IFERROR(INDEX('Medical Examinations'!$F:$F,MATCH($A10,'Medical Examinations'!$A:$A,0)),"Not Found") -> Yes | H10: =IFERROR(INDEX('Medical Examinations'!$L:$L,MATCH($A10,'Medical Examinations'!$A:$A,0)),"Not Found") -> 1 | I10: =IFERROR(INDEX('Medical Examinations'!$K:$K,MATCH($A10,'Medical Examinations'!$A:$A,0)),"Not Found") -> Yes | J10: =IFERROR(INDEX('Medical Examinations'!$M:$M,MATCH($A10,'Medical Examinations'!$A:$A,0)),"Not Found") -> Obesity | K10: =IFERROR(INDEX('Medical Examinations'!$N:$N,MATCH($A10,'Medical Examinations'!$A:$A,0)),"Not Found") -> Diabetic | L10: =IFERROR(INDEX('Hospitalisation Details'!$V:$V,MATCH($A10,'Hospitalisation Details'!$A:$A,0)),"Not Found") -> 0 | M10: =IFERROR(INDEX('Hospitalisation Details'!$F:$F,MATCH($A10,'Hospitalisation Details'!$A:$A,0)),"Not Found") -> 48970.25 | N10: =IFERROR(INDEX('Hospitalisation Details'!$S:$S,MATCH($A10,'Hospitalisation Details'!$A:$A,0)),"Not Found") -> 23258 | O10: =IFERROR(INDEX('Hospitalisation Details'!$T:$T,MATCH($A10,'Hospitalisation Details'!$A:$A,0)),"Not Found") -> 59 | P10: =IFERROR(INDEX('Hospitalisation Details'!$U:$U,MATCH($A10,'Hospitalisation Details'!$A:$A,0)),"Not Found") -> 0 | Q10: =IFERROR(INDEX('Hospitalisation Details'!$W:$W,MATCH($A10,'Hospitalisation Details'!$A:$A,0)),"Not Found") -> 0
A11: ='Customer Names'!A11 -> Id10 | B11: =IFERROR(INDEX('Customer Names'!$D:$D,MATCH($A11,'Customer Names'!$A:$A,0)),"Not Found") -> Brooke N. | C11: =IFERROR(INDEX('Medical Examinations'!$B:$B,MATCH($A11,'Medical Examinations'!$A:$A,0)),"Not Found") -> 38.06 | D11: =IFERROR(INDEX('Medical Examinations'!$C:$C,MATCH($A11,'Medical Examinations'!$A:$A,0)),"Not Found") -> 10.79 | E11: =IFERROR(INDEX('Medical Examinations'!$I:$I,MATCH($A11,'Medical Examinations'!$A:$A,0)),"Not Found") -> No | F11: =IFERROR(INDEX('Medical Examinations'!$J:$J,MATCH($A11,'Medical Examinations'!$A:$A,0)),"Not Found") -> No | G11: =IFERROR(INDEX('Medical Examinations'!$F:$F,MATCH($A11,'Medical Examinations'!$A:$A,0)),"Not Found") -> No | H11: =IFERROR(INDEX('Medical Examinations'!$L:$L,MATCH($A11,'Medical Examinations'!$A:$A,0)),"Not Found") -> 0 | I11: =IFERROR(INDEX('Medical Examinations'!$K:$K,MATCH($A11,'Medical Examinations'!$A:$A,0)),"Not Found") -> Yes | J11: =IFERROR(INDEX('Medical Examinations'!$M:$M,MATCH($A11,'Medical Examinations'!$A:$A,0)),"Not Found") -> Obesity | K11: =IFERROR(INDEX('Medical Examinations'!$N:$N,MATCH($A11,'Medical Examinations'!$A:$A,0)),"Not Found") -> Diabetic | L11: =IFERROR(INDEX('Hospitalisation Details'!$V:$V,MATCH($A11,'Hospitalisation Details'!$A:$A,0)),"Not Found") -> 0 | M11: =IFERROR(INDEX('Hospitalisation Details'!$F:$F,MATCH($A11,'Hospitalisation Details'!$A:$A,0)),"Not Found") -> 48885.14 | N11: =IFERROR(INDEX('Hospitalisation Details'!$S:$S,MATCH($A11,'Hospitalisation Details'!$A:$A,0)),"Not Found") -> 28853 | O11: =IFERROR(INDEX('Hospitalisation Details'!$T:$T,MATCH($A11,'Hospitalisation Details'!$A:$A,0)),"Not Found") -> 44 | P11: =IFERROR(INDEX('Hospitalisation Details'!$U:$U,MATCH($A11,'Hospitalisation Details'!$A:$A,0)),"Not Found") -> 0 | Q11: =IFERROR(INDEX('Hospitalisation Details'!$W:$W,MATCH($A11,'Hospitalisation Details'!$A:$A,0)),"Not Found") -> 0
A12: ='Customer Names'!A12 -> Id11 | B12: =IFERROR(INDEX('Customer Names'!$D:$D,MATCH($A12,'Customer Names'!$A:$A,0)),"Not Found") -> Paola Andrea | C12: =IFERROR(INDEX('Medical Examinations'!$B:$B,MATCH($A12,'Medical Examinations'!$A:$A,0)),"Not Found") -> 37.7 | D12: =IFERROR(INDEX('Medical Examinations'!$C:$C,MATCH($A12,'Medical Examinations'!$A:$A,0)),"Not Found") -> 5.96 | E12: =IFERROR(INDEX('Medical Examinations'!$I:$I,MATCH($A12,'Medical Examinations'!$A:$A,0)),"Not Found") -> Yes | F12: =IFERROR(INDEX('Medical Examinations'!$J:$J,MATCH($A12,'Medical Examinations'!$A:$A,0)),"Not Found") -> No | G12: =IFERROR(INDEX('Medical Examinations'!$F:$F,MATCH($A12,'Medical Examinations'!$A:$A,0)),"Not Found") -> No | H12: =IFERROR(INDEX('Medical Examinations'!$L:$L,MATCH($A12,'Medical Examinations'!$A:$A,0)),"Not Found") -> 2 | I12: =IFERROR(INDEX('Medical Examinations'!$K:$K,MATCH($A12,'Medical Examinations'!$A:$A,0)),"Not Found") -> Yes | J12: =IFERROR(INDEX('Medical Examinations'!$M:$M,MATCH($A12,'Medical Examinations'!$A:$A,0)),"Not Found") -> Obesity | K12: =IFERROR(INDEX('Medical Examinations'!$N:$N,MATCH($A12,'Medical Examinations'!$A:$A,0)),"Not Found") -> Prediabetic | L12: =IFERROR(INDEX('Hospitalisation Details'!$V:$V,MATCH($A12,'Hospitalisation Details'!$A:$A,0)),"Not Found") -> 0 | M12: =IFERROR(INDEX('Hospitalisation Details'!$F:$F,MATCH($A12,'Hospitalisation Details'!$A:$A,0)),"Not Found") -> 48824.45 | N12: =IFERROR(INDEX('Hospitalisation Details'!$S:$S,MATCH($A12,'Hospitalisation Details'!$A:$A,0)),"Not Found") -> 21753 | O12: =IFERROR(INDEX('Hospitalisation Details'!$T:$T,MATCH($A12,'Hospitalisation Details'!$A:$A,0)),"Not Found") -> 63 | P12: =IFERROR(INDEX('Hospitalisation Details'!$U:$U,MATCH($A12,'Hospitalisation Details'!$A:$A,0)),"Not Found") -> 0 | Q12: =IFERROR(INDEX('Hospitalisation Details'!$W:$W,MATCH($A12,'Hospitalisation Details'!$A:$A,0)),"Not Found") -> 0
